
2020-07-04 02:05:52,800 INFO: errors [in C:\Users\Mohamed Hamada\Documents\demos\FSND\projects\01_fyyur\starter_code\app.py:584]
2020-07-04 02:06:11,979 ERROR: Exception on /artists/1 [GET] [in C:\Program Files\Python37\lib\site-packages\flask\app.py:1892]
Traceback (most recent call last):
  File "C:\Program Files\Python37\lib\site-packages\flask\app.py", line 2447, in wsgi_app
    response = self.full_dispatch_request()
  File "C:\Program Files\Python37\lib\site-packages\flask\app.py", line 1952, in full_dispatch_request
    rv = self.handle_user_exception(e)
  File "C:\Program Files\Python37\lib\site-packages\flask\app.py", line 1821, in handle_user_exception
    reraise(exc_type, exc_value, tb)
  File "C:\Program Files\Python37\lib\site-packages\flask\_compat.py", line 39, in reraise
    raise value
  File "C:\Program Files\Python37\lib\site-packages\flask\app.py", line 1950, in full_dispatch_request
    rv = self.dispatch_request()
  File "C:\Program Files\Python37\lib\site-packages\flask\app.py", line 1936, in dispatch_request
    return self.view_functions[rule.endpoint](**req.view_args)
  File "C:\Users\Mohamed Hamada\Documents\demos\FSND\projects\01_fyyur\starter_code\app.py", line 377, in show_artist
    data = list(filter(lambda d: d['id'] == artist_id, [data1, data2, data3]))[0]
IndexError: list index out of range
2020-07-04 02:06:55,931 ERROR: Exception on /shows/create [POST] [in C:\Program Files\Python37\lib\site-packages\flask\app.py:1892]
Traceback (most recent call last):
  File "C:\Program Files\Python37\lib\site-packages\sqlalchemy\engine\base.py", line 1284, in _execute_context
    cursor, statement, parameters, context
  File "C:\Program Files\Python37\lib\site-packages\sqlalchemy\engine\default.py", line 590, in do_execute
    cursor.execute(statement, parameters)
psycopg2.errors.ForeignKeyViolation: insert or update on table "Show" violates foreign key constraint "Show_artist_id_fkey"
DETAIL:  Key (artist_id)=(3) is not present in table "Artist".


The above exception was the direct cause of the following exception:

Traceback (most recent call last):
  File "C:\Program Files\Python37\lib\site-packages\flask\app.py", line 2447, in wsgi_app
    response = self.full_dispatch_request()
  File "C:\Program Files\Python37\lib\site-packages\flask\app.py", line 1952, in full_dispatch_request
    rv = self.handle_user_exception(e)
  File "C:\Program Files\Python37\lib\site-packages\flask\app.py", line 1821, in handle_user_exception
    reraise(exc_type, exc_value, tb)
  File "C:\Program Files\Python37\lib\site-packages\flask\_compat.py", line 39, in reraise
    raise value
  File "C:\Program Files\Python37\lib\site-packages\flask\app.py", line 1950, in full_dispatch_request
    rv = self.dispatch_request()
  File "C:\Program Files\Python37\lib\site-packages\flask\app.py", line 1936, in dispatch_request
    return self.view_functions[rule.endpoint](**req.view_args)
  File "C:\Users\Mohamed Hamada\Documents\demos\FSND\projects\01_fyyur\starter_code\app.py", line 555, in create_show_submission
    db.session.commit()
  File "C:\Program Files\Python37\lib\site-packages\sqlalchemy\orm\scoping.py", line 163, in do
    return getattr(self.registry(), name)(*args, **kwargs)
  File "C:\Program Files\Python37\lib\site-packages\sqlalchemy\orm\session.py", line 1042, in commit
    self.transaction.commit()
  File "C:\Program Files\Python37\lib\site-packages\sqlalchemy\orm\session.py", line 504, in commit
    self._prepare_impl()
  File "C:\Program Files\Python37\lib\site-packages\sqlalchemy\orm\session.py", line 483, in _prepare_impl
    self.session.flush()
  File "C:\Program Files\Python37\lib\site-packages\sqlalchemy\orm\session.py", line 2523, in flush
    self._flush(objects)
  File "C:\Program Files\Python37\lib\site-packages\sqlalchemy\orm\session.py", line 2664, in _flush
    transaction.rollback(_capture_exception=True)
  File "C:\Program Files\Python37\lib\site-packages\sqlalchemy\util\langhelpers.py", line 69, in __exit__
    exc_value, with_traceback=exc_tb,
  File "C:\Program Files\Python37\lib\site-packages\sqlalchemy\util\compat.py", line 178, in raise_
    raise exception
  File "C:\Program Files\Python37\lib\site-packages\sqlalchemy\orm\session.py", line 2624, in _flush
    flush_context.execute()
  File "C:\Program Files\Python37\lib\site-packages\sqlalchemy\orm\unitofwork.py", line 422, in execute
    rec.execute(self)
  File "C:\Program Files\Python37\lib\site-packages\sqlalchemy\orm\unitofwork.py", line 589, in execute
    uow,
  File "C:\Program Files\Python37\lib\site-packages\sqlalchemy\orm\persistence.py", line 245, in save_obj
    insert,
  File "C:\Program Files\Python37\lib\site-packages\sqlalchemy\orm\persistence.py", line 1136, in _emit_insert_statements
    statement, params
  File "C:\Program Files\Python37\lib\site-packages\sqlalchemy\engine\base.py", line 1020, in execute
    return meth(self, multiparams, params)
  File "C:\Program Files\Python37\lib\site-packages\sqlalchemy\sql\elements.py", line 298, in _execute_on_connection
    return connection._execute_clauseelement(self, multiparams, params)
  File "C:\Program Files\Python37\lib\site-packages\sqlalchemy\engine\base.py", line 1139, in _execute_clauseelement
    distilled_params,
  File "C:\Program Files\Python37\lib\site-packages\sqlalchemy\engine\base.py", line 1324, in _execute_context
    e, statement, parameters, cursor, context
  File "C:\Program Files\Python37\lib\site-packages\sqlalchemy\engine\base.py", line 1518, in _handle_dbapi_exception
    sqlalchemy_exception, with_traceback=exc_info[2], from_=e
  File "C:\Program Files\Python37\lib\site-packages\sqlalchemy\util\compat.py", line 178, in raise_
    raise exception
  File "C:\Program Files\Python37\lib\site-packages\sqlalchemy\engine\base.py", line 1284, in _execute_context
    cursor, statement, parameters, context
  File "C:\Program Files\Python37\lib\site-packages\sqlalchemy\engine\default.py", line 590, in do_execute
    cursor.execute(statement, parameters)
sqlalchemy.exc.IntegrityError: (psycopg2.errors.ForeignKeyViolation) insert or update on table "Show" violates foreign key constraint "Show_artist_id_fkey"
DETAIL:  Key (artist_id)=(3) is not present in table "Artist".

[SQL: INSERT INTO "Show" (start_time, artist_id, venue_id) VALUES (%(start_time)s, %(artist_id)s, %(venue_id)s) RETURNING "Show".id]
[parameters: {'start_time': datetime.datetime(2020, 7, 4, 2, 5, 52), 'artist_id': '3', 'venue_id': '1'}]
(Background on this error at: http://sqlalche.me/e/gkpj)
2020-07-04 02:07:23,809 ERROR: Exception on /shows/create [POST] [in C:\Program Files\Python37\lib\site-packages\flask\app.py:1892]
Traceback (most recent call last):
  File "C:\Program Files\Python37\lib\site-packages\sqlalchemy\engine\base.py", line 1284, in _execute_context
    cursor, statement, parameters, context
  File "C:\Program Files\Python37\lib\site-packages\sqlalchemy\engine\default.py", line 590, in do_execute
    cursor.execute(statement, parameters)
psycopg2.errors.ForeignKeyViolation: insert or update on table "Show" violates foreign key constraint "Show_artist_id_fkey"
DETAIL:  Key (artist_id)=(3) is not present in table "Artist".


The above exception was the direct cause of the following exception:

Traceback (most recent call last):
  File "C:\Program Files\Python37\lib\site-packages\flask\app.py", line 2447, in wsgi_app
    response = self.full_dispatch_request()
  File "C:\Program Files\Python37\lib\site-packages\flask\app.py", line 1952, in full_dispatch_request
    rv = self.handle_user_exception(e)
  File "C:\Program Files\Python37\lib\site-packages\flask\app.py", line 1821, in handle_user_exception
    reraise(exc_type, exc_value, tb)
  File "C:\Program Files\Python37\lib\site-packages\flask\_compat.py", line 39, in reraise
    raise value
  File "C:\Program Files\Python37\lib\site-packages\flask\app.py", line 1950, in full_dispatch_request
    rv = self.dispatch_request()
  File "C:\Program Files\Python37\lib\site-packages\flask\app.py", line 1936, in dispatch_request
    return self.view_functions[rule.endpoint](**req.view_args)
  File "C:\Users\Mohamed Hamada\Documents\demos\FSND\projects\01_fyyur\starter_code\app.py", line 555, in create_show_submission
    db.session.commit()
  File "C:\Program Files\Python37\lib\site-packages\sqlalchemy\orm\scoping.py", line 163, in do
    return getattr(self.registry(), name)(*args, **kwargs)
  File "C:\Program Files\Python37\lib\site-packages\sqlalchemy\orm\session.py", line 1042, in commit
    self.transaction.commit()
  File "C:\Program Files\Python37\lib\site-packages\sqlalchemy\orm\session.py", line 504, in commit
    self._prepare_impl()
  File "C:\Program Files\Python37\lib\site-packages\sqlalchemy\orm\session.py", line 483, in _prepare_impl
    self.session.flush()
  File "C:\Program Files\Python37\lib\site-packages\sqlalchemy\orm\session.py", line 2523, in flush
    self._flush(objects)
  File "C:\Program Files\Python37\lib\site-packages\sqlalchemy\orm\session.py", line 2664, in _flush
    transaction.rollback(_capture_exception=True)
  File "C:\Program Files\Python37\lib\site-packages\sqlalchemy\util\langhelpers.py", line 69, in __exit__
    exc_value, with_traceback=exc_tb,
  File "C:\Program Files\Python37\lib\site-packages\sqlalchemy\util\compat.py", line 178, in raise_
    raise exception
  File "C:\Program Files\Python37\lib\site-packages\sqlalchemy\orm\session.py", line 2624, in _flush
    flush_context.execute()
  File "C:\Program Files\Python37\lib\site-packages\sqlalchemy\orm\unitofwork.py", line 422, in execute
    rec.execute(self)
  File "C:\Program Files\Python37\lib\site-packages\sqlalchemy\orm\unitofwork.py", line 589, in execute
    uow,
  File "C:\Program Files\Python37\lib\site-packages\sqlalchemy\orm\persistence.py", line 245, in save_obj
    insert,
  File "C:\Program Files\Python37\lib\site-packages\sqlalchemy\orm\persistence.py", line 1136, in _emit_insert_statements
    statement, params
  File "C:\Program Files\Python37\lib\site-packages\sqlalchemy\engine\base.py", line 1020, in execute
    return meth(self, multiparams, params)
  File "C:\Program Files\Python37\lib\site-packages\sqlalchemy\sql\elements.py", line 298, in _execute_on_connection
    return connection._execute_clauseelement(self, multiparams, params)
  File "C:\Program Files\Python37\lib\site-packages\sqlalchemy\engine\base.py", line 1139, in _execute_clauseelement
    distilled_params,
  File "C:\Program Files\Python37\lib\site-packages\sqlalchemy\engine\base.py", line 1324, in _execute_context
    e, statement, parameters, cursor, context
  File "C:\Program Files\Python37\lib\site-packages\sqlalchemy\engine\base.py", line 1518, in _handle_dbapi_exception
    sqlalchemy_exception, with_traceback=exc_info[2], from_=e
  File "C:\Program Files\Python37\lib\site-packages\sqlalchemy\util\compat.py", line 178, in raise_
    raise exception
  File "C:\Program Files\Python37\lib\site-packages\sqlalchemy\engine\base.py", line 1284, in _execute_context
    cursor, statement, parameters, context
  File "C:\Program Files\Python37\lib\site-packages\sqlalchemy\engine\default.py", line 590, in do_execute
    cursor.execute(statement, parameters)
sqlalchemy.exc.IntegrityError: (psycopg2.errors.ForeignKeyViolation) insert or update on table "Show" violates foreign key constraint "Show_artist_id_fkey"
DETAIL:  Key (artist_id)=(3) is not present in table "Artist".

[SQL: INSERT INTO "Show" (start_time, artist_id, venue_id) VALUES (%(start_time)s, %(artist_id)s, %(venue_id)s) RETURNING "Show".id]
[parameters: {'start_time': datetime.datetime(2020, 7, 4, 2, 5, 52), 'artist_id': '3', 'venue_id': '1'}]
(Background on this error at: http://sqlalche.me/e/gkpj)
